File: data/ETMT_data/065_ETMT.txt
# Load (N), Position (mm), Engineering Stress (MPa), True Strain, True Stress (MPa), Temperature (C)
3.325199708342549965e-01,3.325199708342549965e-01,3.146019298583275225e-01,0.000000000000000000e+00,3.146019298583275225e-01,9.001445537433030495e+02
3.387417178601029866e-01,3.387417178601029866e-01,9.140158072113999665e+00,-1.515800279370947310e-04,9.138772711697217943e+00,8.953789835795760155e+02
3.508734051138159837e-01,3.508734051138159837e-01,2.244183211587370153e+01,5.191091647369352677e-04,2.245348490087060611e+01,8.982774526812139584e+02
3.617068286985160031e-01,3.617068286985160031e-01,3.130579600110650063e+01,1.162855432460572092e-03,3.134222129062216311e+01,9.002938508056099636e+02
3.740566316992040008e-01,3.740566316992040008e-01,4.021879984065900260e+01,1.829554472852510999e-03,4.029244967845149716e+01,9.015158009715380558e+02
3.865667618811129969e-01,3.865667618811129969e-01,4.634542041458200146e+01,2.638193179122384508e-03,4.646785001205800114e+01,9.018855672329659683e+02
3.981525078415870111e-01,3.981525078415870111e-01,4.948088084347549653e+01,3.570861464339970381e-03,4.965788605656475596e+01,9.033676567487419788e+02
4.093543160706760164e-01,4.093543160706760164e-01,5.119295208714900269e+01,4.586275762225846576e-03,5.142827630088943636e+01,9.040210917592049782e+02
4.216923844069240257e-01,4.216923844069240257e-01,5.291295703500500025e+01,5.737322463068910035e-03,5.321740826429638105e+01,9.040391240268950241e+02
4.341017920523880247e-01,4.341017920523880247e-01,5.324659170582899748e+01,7.057286801733578252e-03,5.362369728065658592e+01,9.049123520962890552e+02
4.456771072000270117e-01,4.456771072000270117e-01,5.237048375420275192e+01,8.373441174031569234e-03,5.281084601995863892e+01,9.042533640749750248e+02
4.570986144244669758e-01,4.570986144244669758e-01,5.211703828535974736e+01,9.694486186267526132e-03,5.262474318585975652e+01,9.047099989838900456e+02
4.696718882769350123e-01,4.696718882769350123e-01,5.243685678578925291e+01,1.108864032858746830e-02,5.302154594353317663e+01,9.048253046348689850e+02
4.820949863642450262e-01,4.820949863642450262e-01,5.202301312237975139e+01,1.257070687892550796e-02,5.268110685689607209e+01,9.046975560486320092e+02
4.940470680594439834e-01,4.940470680594439834e-01,5.135097773745650329e+01,1.420629545302805850e-02,5.208569132157656156e+01,9.053526255302130039e+02
5.055212881416080162e-01,5.055212881416080162e-01,5.079219932667899684e+01,1.561276259059093431e-02,5.159142873085398406e+01,9.045017827302219757e+02
5.180741660296920292e-01,5.180741660296920292e-01,5.104585783556100154e+01,1.705650635294761810e-02,5.192398947390151420e+01,9.046160252764819916e+02
5.307800602167840331e-01,5.307800602167840331e-01,5.100048962049174861e+01,1.856914686151246371e-02,5.195637270232616345e+01,9.049111157655720490e+02
5.428276956081390381e-01,5.428276956081390381e-01,5.030814441852275110e+01,2.008047422915443941e-02,5.132856681068410865e+01,9.054074571467939450e+02
5.541319958865640327e-01,5.541319958865640327e-01,4.957728902809324723e+01,2.162584779370905347e-02,5.066111704468337251e+01,9.055862193927169983e+02
5.667575635015960067e-01,5.667575635015960067e-01,5.013816291466350350e+01,2.311988686553606911e-02,5.131085559386032457e+01,9.056129772216080482e+02
5.792656447738410153e-01,5.792656447738410153e-01,4.993266426026824689e+01,2.459546668829548297e-02,5.117600908571750296e+01,9.051970629952850231e+02
5.911038257181639999e-01,5.911038257181639999e-01,4.931759787723424893e+01,2.618708959517732082e-02,5.062614091999660815e+01,9.056670279242099468e+02
6.021413486450909458e-01,6.021413486450909458e-01,4.840883077122275324e+01,2.771806241666964141e-02,4.976939881074723360e+01,9.056146563962099663e+02
6.139412987977269642e-01,6.139412987977269642e-01,4.873725352808825306e+01,2.917695568329608385e-02,5.018020633607608971e+01,9.056059629656369907e+02
6.264044437557459988e-01,6.264044437557459988e-01,4.918131045997149897e+01,3.082872589409893505e-02,5.072112084299059376e+01,9.057969599962229950e+02
6.383677478879690170e-01,6.383677478879690170e-01,4.869788070209325070e+01,3.239512489090948244e-02,5.030128566008686164e+01,9.053631518036130501e+02
6.496298126876359769e-01,6.496298126876359769e-01,4.782642819918699928e+01,3.378434754961884973e-02,4.946981697201268702e+01,9.050597562454639728e+02
6.618169602006670482e-01,6.618169602006670482e-01,4.847706179134549842e+01,3.527663360568507323e-02,5.021769059532699231e+01,9.054421777836979572e+02
6.746133789420130089e-01,6.746133789420130089e-01,4.888725467026225147e+01,3.683462722788070909e-02,5.072157431830852659e+01,9.054170572198929676e+02
6.865703035146000222e-01,6.865703035146000222e-01,4.818456829525524654e+01,3.840400103138416621e-02,5.007104069746478103e+01,9.053648351691659855e+02
6.980412639677530118e-01,6.980412639677530118e-01,4.743117839097975263e+01,4.001923152253319960e-02,4.936783091139617596e+01,9.060220308601859642e+02
7.095304317772389568e-01,7.095304317772389568e-01,4.749747808091350265e+01,4.152909200725037053e-02,4.951153677620801830e+01,9.051226708106700016e+02
7.220072671771049500e-01,7.220072671771049500e-01,4.807448247447599954e+01,4.315153396812729941e-02,5.019437960769057838e+01,9.053514562547210289e+02
7.348535582423210144e-01,7.348535582423210144e-01,4.819716908968975133e+01,4.476175210002325544e-02,5.040357166082827689e+01,9.057172215543689617e+02
7.466524373739960030e-01,7.466524373739960030e-01,4.741113516502075242e+01,4.640417901231701919e-02,4.966305513433805885e+01,9.057494164444509579e+02
7.581146433949470520e-01,7.581146433949470520e-01,4.717395524494349957e+01,4.797011785017760849e-02,4.949205058761693010e+01,9.054663470014929771e+02
7.709926925599579484e-01,7.709926925599579484e-01,4.787525977008049693e+01,4.948898401471502756e-02,5.030416402656883434e+01,9.057631851173939594e+02
7.834316231310369805e-01,7.834316231310369805e-01,4.745387588627625064e+01,5.118775575351536267e-02,4.994617677190151994e+01,9.052203227765860447e+02
7.950872182846070446e-01,7.950872182846070446e-01,4.687608685344449810e+01,5.276837667966441381e-02,4.941608838131953974e+01,9.053689730353650020e+02
8.061706554144619785e-01,8.061706554144619785e-01,4.615955287590625034e+01,5.434260725708646433e-02,4.873739222708636021e+01,9.051194842904809548e+02
8.181885816156859725e-01,8.181885816156859725e-01,4.670670605264599828e+01,5.587779770407209218e-02,4.939086808996485445e+01,9.046901506371799542e+02
8.307195268571380131e-01,8.307195268571380131e-01,4.703484009951350231e+01,5.747058581365389190e-02,4.981714448868306988e+01,9.048526142723859493e+02
8.426706772297619663e-01,8.426706772297619663e-01,4.657903104089199786e+01,5.908820115118008920e-02,4.941424106659032844e+01,9.043480474501850495e+02
8.539672475308179855e-01,8.539672475308179855e-01,4.575984086841349807e+01,6.067225811088198389e-02,4.862214704643648133e+01,9.045291845686730312e+02
8.662439417093990013e-01,8.662439417093990013e-01,4.657994839362800121e+01,6.226864694938304828e-02,4.957262685647575751e+01,9.046401316300029976e+02
8.790702093392610550e-01,8.790702093392610550e-01,4.672453273087749892e+01,6.394302686113460810e-02,4.980983127679610334e+01,9.044539891183379723e+02
8.910290431231260300e-01,8.910290431231260300e-01,4.615498939529049949e+01,6.562531662718336378e-02,4.928552287664896170e+01,9.049569102935489582e+02
9.026863146573309571e-01,9.026863146573309571e-01,4.566802876070150319e+01,6.727008882232012044e-02,4.884580757616831903e+01,9.053456825204190181e+02
9.145904798060660035e-01,9.145904798060660035e-01,4.590111551806324997e+01,6.869729284976872075e-02,4.916523228622597941e+01,9.042924209497870152e+02
9.278399869799619504e-01,9.278399869799619504e-01,4.683998064138000217e+01,7.043346913008749488e-02,5.025804303691671038e+01,9.048371105454859844e+02
9.404002688825130463e-01,9.404002688825130463e-01,4.628560156561425032e+01,7.222842631389136958e-02,4.975243254256176328e+01,9.050387623719869907e+02
9.520798455923800141e-01,9.520798455923800141e-01,4.527566372416924878e+01,7.392855043314915109e-02,4.874965955504698201e+01,9.049618011340500061e+02
9.641486685723069661e-01,9.641486685723069661e-01,4.563545691780750246e+01,7.549230032960710379e-02,4.921395781497731292e+01,9.045202299021179897e+02
9.772648103535179764e-01,9.772648103535179764e-01,4.629761679098000116e+01,7.721508874056889904e-02,5.001413049047372539e+01,9.051717356778680141e+02
9.893403388559820488e-01,9.893403388559820488e-01,4.548663040623075204e+01,7.882406265808834800e-02,4.921716812252450524e+01,9.047534186393020263e+02
1.001024106517429901e+00,1.001024106517429901e+00,4.482422373257575288e+01,8.051050045841635916e-02,4.858229684342123988e+01,9.047391680069270024e+02
1.012331806123260014e+00,1.012331806123260014e+00,4.463605931960049844e+01,8.205996226876478838e-02,4.845337520355858629e+01,9.043857576325540322e+02
1.024746987968679912e+00,1.024746987968679912e+00,4.523806623183200060e+01,8.375053248267483319e-02,4.918995510702780649e+01,9.041418232955039684e+02
1.037005940452220054e+00,1.037005940452220054e+00,4.500749404542150245e+01,8.545499464018684044e-02,4.902272690098828178e+01,9.045921773649749866e+02
1.048873411491509922e+00,1.048873411491509922e+00,4.463346209377049689e+01,8.707339333700631068e-02,4.869406929151947594e+01,9.037257470190529602e+02
1.060184277594089952e+00,1.060184277594089952e+00,4.429520107805724649e+01,8.867994308020331340e-02,4.840273335739532001e+01,9.048098232597110382e+02
1.072980696335430029e+00,1.072980696335430029e+00,4.509086022153500295e+01,9.038159400136408506e-02,4.935609007944356108e+01,9.046938302926720326e+02
1.085240766406059931e+00,1.085240766406059931e+00,4.467850551009175319e+01,9.213952466642687245e-02,4.899077668935132834e+01,9.049749369733040112e+02
1.097098737955090053e+00,1.097098737955090053e+00,4.433402791619300132e+01,9.378607078039037648e-02,4.869316043896682089e+01,9.053098652511839646e+02
1.108289742842319958e+00,1.108289742842319958e+00,4.382665501907474948e+01,9.530735780066572349e-02,4.820918447429527021e+01,9.047665363177660538e+02
1.120838616043329905e+00,1.120838616043329905e+00,4.454812733456500240e+01,9.688107723513310343e-02,4.907997915508581599e+01,9.037323128432039994e+02
1.133763045072559983e+00,1.133763045072559983e+00,4.473544657230375066e+01,9.870824110220496883e-02,4.937649082390950639e+01,9.041351778432730271e+02
1.145601971074940106e+00,1.145601971074940106e+00,4.392841248773049756e+01,1.004133134930191018e-01,4.856847381637730621e+01,9.035319560207429959e+02
1.156977983191610049e+00,1.156977983191610049e+00,4.351278534159074951e+01,1.020334915251173424e-01,4.818695312364904026e+01,9.037326271645720226e+02
1.169597823172809914e+00,1.169597823172809914e+00,4.416642244905224857e+01,1.037635647033170044e-01,4.899549680706598309e+01,9.040821692906320095e+02
1.181895285844799970e+00,1.181895285844799970e+00,4.377482109703124991e+01,1.054794320952879283e-01,4.864447439147930652e+01,9.038262977264820393e+02
1.193590508773920034e+00,1.193590508773920034e+00,4.331577336415649881e+01,1.071811304784847652e-01,4.821634059417642248e+01,9.042199663817880264e+02
1.204515900462870048e+00,1.204515900462870048e+00,4.264184972271325336e+01,1.087536469648728160e-01,4.754087207881661215e+01,9.040323654189710396e+02
1.216528983786699936e+00,1.216528983786699936e+00,4.317524028010674897e+01,1.104233026348374336e-01,4.821597954347412696e+01,9.038503593765200321e+02
1.228831289336089982e+00,1.228831289336089982e+00,4.334574448876075081e+01,1.122851788125299038e-01,4.849660089611528946e+01,9.048217074014249874e+02
1.240513799712060106e+00,1.240513799712060106e+00,4.289044532924899755e+01,1.139586429723717376e-01,4.806756976706449080e+01,9.040354094468060566e+02
1.251636212691660033e+00,1.251636212691660033e+00,4.239681526087225194e+01,1.155815264249623053e-01,4.759152856475697035e+01,9.046033085323870182e+02
1.264002360403539971e+00,1.264002360403539971e+00,4.315629834309225288e+01,1.173407642904975706e-01,4.852936773925509328e+01,9.043945823796090053e+02
1.276372186839580092e+00,1.276372186839580092e+00,4.318988765589899970e+01,1.190970541149535961e-01,4.865251192720968021e+01,9.045461174100639710e+02
1.288155186921360107e+00,1.288155186921360107e+00,4.275377024896449996e+01,1.208276978083672043e-01,4.824465682431980440e+01,9.052921403199429733e+02
1.299488684162499963e+00,1.299488684162499963e+00,4.222394432872525272e+01,1.224712093855164913e-01,4.772515754330689219e+01,9.049054426141079830e+02
1.311529194936160048e+00,1.311529194936160048e+00,4.264358431100850311e+01,1.240998389459052609e-01,4.827803402377511333e+01,9.046266786754130180e+02
1.324206823483109918e+00,1.324206823483109918e+00,4.322077846154574843e+01,1.259570183424267020e-01,4.902245119674838492e+01,9.052360667847100331e+02
1.336466427892450071e+00,1.336466427892450071e+00,4.272835911251600294e+01,1.277062351524891892e-01,4.854878082941988993e+01,9.043574938550590332e+02
1.347963139414789957e+00,1.347963139414789957e+00,4.202654003165650209e+01,1.294417246555650824e-01,4.783430447249494222e+01,9.045764249749480541e+02
1.360118947923180110e+00,1.360118947923180110e+00,4.250623518601049966e+01,1.310997443973530574e-01,4.846057204641843441e+01,9.042008584365249817e+02
1.372719928622250007e+00,1.372719928622250007e+00,4.269557190127675028e+01,1.329781785972021235e-01,4.876795273621856808e+01,9.033064632676539532e+02
1.384633453562859939e+00,1.384633453562859939e+00,4.205545876175175124e+01,1.348629980686217589e-01,4.812742553365910680e+01,9.046133793890479637e+02
1.395980408415200102e+00,1.395980408415200102e+00,4.135222989134499727e+01,1.365445428452072563e-01,4.740230660644079563e+01,9.038843661546710564e+02
1.407389761880039947e+00,1.407389761880039947e+00,4.138692398555574670e+01,1.381843143652503880e-01,4.751993463594421030e+01,9.032079563476149815e+02
1.419544732198120052e+00,1.419544732198120052e+00,4.180797841399900250e+01,1.400509086424457650e-01,4.809307044341881010e+01,9.039529860019680427e+02
1.431716838851569973e+00,1.431716838851569973e+00,4.179063253104674658e+01,1.419079618238376084e-01,4.816247419259219953e+01,9.043743149377410191e+02
1.443320745602250099e+00,1.443320745602250099e+00,4.126776708289975204e+01,1.436178000000172539e-01,4.764127642241372484e+01,9.035786362364890465e+02
1.454944955185059952e+00,1.454944955185059952e+00,4.140398115850975103e+01,1.453764548789631128e-01,4.788266285542005107e+01,9.043892389163370353e+02
1.467625983059410055e+00,1.467625983059410055e+00,4.191014100797475095e+01,1.472180233397975269e-01,4.855736341228723774e+01,9.040468479506670292e+02
1.479920651763680040e+00,1.479920651763680040e+00,4.153605666942900143e+01,1.490315305248216260e-01,4.821129915806396582e+01,9.035734101198610233e+02
1.491764187812810061e+00,1.491764187812810061e+00,4.117356496863074966e+01,1.509195557953284805e-01,4.788086656667316277e+01,9.046362312510609627e+02
1.503066113218670008e+00,1.503066113218670008e+00,4.083958454430099749e+01,1.525769619276311773e-01,4.757125928798298986e+01,9.042554902844129856e+02
1.515328465029599947e+00,1.515328465029599947e+00,4.121379344724125104e+01,1.543824412558136017e-01,4.809390404214425985e+01,9.041612623259429711e+02
1.528108958154920094e+00,1.528108958154920094e+00,4.146664054133000121e+01,1.563264570201713943e-01,4.848312109081162191e+01,9.048595656640829930e+02
1.540061272680760096e+00,1.540061272680760096e+00,4.092497751116749782e+01,1.581342885113988794e-01,4.793638705410154444e+01,9.042078754864629673e+02
1.551395747810599968e+00,1.551395747810599968e+00,4.035241552628575334e+01,1.599868211193461176e-01,4.735337422229535065e+01,9.045929429121320027e+02
1.564029417932029986e+00,1.564029417932029986e+00,4.112967872060824703e+01,1.618581432476496884e-01,4.835589384924713841e+01,9.042896800674500355e+02
1.576767489314079951e+00,1.576767489314079951e+00,4.109808942303050117e+01,1.638563912365539610e-01,4.841540390561782203e+01,9.044380579143760315e+02
1.588462619110940111e+00,1.588462619110940111e+00,4.042214713990699693e+01,1.656517729133063221e-01,4.770468467118898559e+01,9.043174716643990223e+02
1.599686965346339917e+00,1.599686965346339917e+00,3.977650427259499821e+01,1.674299782024631089e-01,4.702626950751192680e+01,9.043888393789529800e+02
1.611335808411239912e+00,1.611335808411239912e+00,4.012588877230874829e+01,1.691361722706146709e-01,4.752034350002657703e+01,9.037664034403859432e+02
1.623929850757120041e+00,1.623929850757120041e+00,4.071878502145400347e+01,1.711383248461519346e-01,4.831914501541724150e+01,9.048714512027800083e+02
1.636041281744839981e+00,1.636041281744839981e+00,4.030946874991050066e+01,1.729410094676351040e-01,4.791973421670120814e+01,9.041505111381410416e+02
1.647644676268100072e+00,1.647644676268100072e+00,3.976581851020449676e+01,1.747447875621983004e-01,4.735879275537380551e+01,9.036904885433609707e+02
1.659125555306669941e+00,1.659125555306669941e+00,3.978322609327724990e+01,1.765651864844518526e-01,4.746585236804227037e+01,9.039860526099799927e+02
1.671960204839709974e+00,1.671960204839709974e+00,4.040903411805624756e+01,1.785087209247193107e-01,4.830630534951863808e+01,9.041571523994209656e+02
1.684203557670119977e+00,1.684203557670119977e+00,3.998563857749100237e+01,1.803736476772612729e-01,4.788939119770742536e+01,9.036236791871490368e+02
1.696159131824970023e+00,1.696159131824970023e+00,3.972798120230424956e+01,1.823146788424204190e-01,4.767324954733761189e+01,9.048964935354889576e+02
1.707536354660990074e+00,1.707536354660990074e+00,3.927553072571750192e+01,1.842088835897197074e-01,4.721967177728263465e+01,9.046485344879330341e+02
1.719874190166589933e+00,1.719874190166589933e+00,3.982687718234949870e+01,1.860744908126292785e-01,4.797195077625234205e+01,9.040205818600950352e+02
1.732909074053170073e+00,1.732909074053170073e+00,4.011868266388775339e+01,1.882543703142958158e-01,4.842888813530613135e+01,9.047722569666799473e+02
1.745224697515370016e+00,1.745224697515370016e+00,3.966628806665549689e+01,1.902508938363713931e-01,4.797847887984764270e+01,9.047073461115360260e+02
1.756645506247880073e+00,1.756645506247880073e+00,3.894794615916899971e+01,1.921235073256812032e-01,4.719790698470582413e+01,9.048373368568719570e+02
1.769141294062140046e+00,1.769141294062140046e+00,3.966000629588950233e+01,1.940066932689127888e-01,4.815138851497351880e+01,9.046161537989969474e+02
1.781822927296160097e+00,1.781822927296160097e+00,3.953970270231374684e+01,1.960153479307398527e-01,4.810185042448803472e+01,9.047005902975799927e+02
1.793623901903629969e+00,1.793623901903629969e+00,3.896975307725374904e+01,1.979753575285638501e-01,4.750149292908209020e+01,9.042445952072739601e+02
1.804877538234000101e+00,1.804877538234000101e+00,3.825545427389450026e+01,1.998416907017052935e-01,4.671792089808055692e+01,9.041332094930110088e+02
1.816461328417060095e+00,1.816461328417060095e+00,3.856236464343975001e+01,2.016369960587851007e-01,4.717734448625364507e+01,9.039684687741099651e+02
1.829136209562419957e+00,1.829136209562419957e+00,3.921150928363199739e+01,2.037286193194018935e-01,4.807195385884396188e+01,9.042068570852279663e+02
1.841314788907769895e+00,1.841314788907769895e+00,3.885551937855775151e+01,2.057193866234094393e-01,4.773044824763999117e+01,9.048277465626599678e+02
1.852773921564220050e+00,1.852773921564220050e+00,3.801517304964374944e+01,2.075474859482082657e-01,4.678360667135030582e+01,9.036281425505879952e+02
1.864592451602220091e+00,1.864592451602220091e+00,3.849422209896150093e+01,2.094389230912390987e-01,4.746283946312229318e+01,9.041007980704309830e+02
1.877459930256009990e+00,1.877459930256009990e+00,3.894705325365075055e+01,2.115008510809524567e-01,4.812029232206905505e+01,9.042793437838549835e+02
1.889551104977730045e+00,1.889551104977730045e+00,3.838216187432399806e+01,2.135212212479422056e-01,4.751825905756266621e+01,9.041442554444070083e+02
1.901027187705039978e+00,1.901027187705039978e+00,3.775088698603224913e+01,2.155238999273354772e-01,4.683041437566558329e+01,9.049543105065820328e+02
1.912625366821889994e+00,1.912625366821889994e+00,3.795607364736500244e+01,2.173561613376280566e-01,4.717130183856515657e+01,9.042997090145950096e+02
1.925445161759850032e+00,1.925445161759850032e+00,3.859973629005249762e+01,2.193876955196807088e-01,4.806879144873850151e+01,9.042917601764199844e+02
1.938371593132619974e+00,1.938371593132619974e+00,3.852074849419300051e+01,2.215145033846224465e-01,4.807255929249357251e+01,9.046734482981260044e+02
1.949943136423829992e+00,1.949943136423829992e+00,3.755274461582300205e+01,2.235459237705244295e-01,4.695982230785669032e+01,9.042714228853579925e+02
1.961527997627849906e+00,1.961527997627849906e+00,3.764414228498925041e+01,2.254817365860696254e-01,4.716533030830066764e+01,9.043613369576629566e+02
1.974280644208189939e+00,1.974280644208189939e+00,3.815081901848324719e+01,2.275441415550556457e-01,4.789884385225688845e+01,9.041862417943780201e+02
1.986575918272140084e+00,1.986575918272140084e+00,3.767178626731050173e+01,2.295706384819366230e-01,4.739335731711524602e+01,9.034909475594760124e+02
1.998110674321649904e+00,1.998110674321649904e+00,3.704240196384500194e+01,2.315832845185929467e-01,4.669544115161841802e+01,9.038088130764659809e+02
2.009010361507539866e+00,2.009010361507539866e+00,3.662017639726399665e+01,2.333886413412087912e-01,4.624660230300940356e+01,9.036631830967960468e+02
2.020964771509170088e+00,2.020964771509170088e+00,3.706720308400699793e+01,2.353287522861685910e-01,4.690204683422255272e+01,9.036989989690480343e+02
2.033510385081170213e+00,2.033510385081170213e+00,3.737761639058599883e+01,2.373739614621004912e-01,4.739164723417016489e+01,9.036165629513559452e+02
2.045321045443420083e+00,2.045321045443420083e+00,3.682606038637450041e+01,2.393773457097715662e-01,4.678595742744641228e+01,9.032492637634279617e+02
2.056191908195609930e+00,2.056191908195609930e+00,3.606633981689800095e+01,2.413699882361818316e-01,4.591215990053836293e+01,9.033978777006269638e+02
2.068592095747590065e+00,2.068592095747590065e+00,3.697839798405775014e+01,2.434647962362747053e-01,4.717191527369864446e+01,9.036113074980679585e+02
2.081188745796680006e+00,2.081188745796680006e+00,3.701960085891175112e+01,2.455068741091990525e-01,4.732101078100726710e+01,9.030610704794529511e+02
2.093054121360180098e+00,2.093054121360180098e+00,3.647558158263574768e+01,2.476354062593640326e-01,4.672495756864193339e+01,9.040236035361889435e+02
2.104238141328099942e+00,2.104238141328099942e+00,3.572188667021700326e+01,2.494967116962250320e-01,4.584473149225872390e+01,9.035910107195379624e+02
2.116100257262590212e+00,2.116100257262590212e+00,3.621807671152050290e+01,2.515366946210618182e-01,4.657644985573742247e+01,9.035298870876430328e+02
2.128616767004130050e+00,2.128616767004130050e+00,3.657347755506624765e+01,2.536327465218058963e-01,4.713218341085175922e+01,9.038288262672720066e+02
2.141064498573539865e+00,2.141064498573539865e+00,3.632850362919275256e+01,2.557794497360169061e-01,4.691709494613709808e+01,9.042593012563879711e+02
2.152392454445359871e+00,2.152392454445359871e+00,3.546475549228500057e+01,2.578457599893851371e-01,4.589633013027066255e+01,9.047429426573220326e+02
2.164367819204930043e+00,2.164367819204930043e+00,3.603169461712249699e+01,2.598943118821920306e-01,4.672565021550322939e+01,9.050888568162920365e+02
2.177080092951659829e+00,2.177080092951659829e+00,3.636213717982175098e+01,2.620340243508747502e-01,4.725517020377597532e+01,9.048466351814570316e+02
2.189258532598609808e+00,2.189258532598609808e+00,3.591172397136700312e+01,2.641683127781705998e-01,4.676953960960269541e+01,9.049280961044130436e+02
2.200769772753119913e+00,2.200769772753119913e+00,3.530802088789649673e+01,2.661634330485497801e-01,4.607514229094755365e+01,9.042016784660520443e+02
2.211859636008739916e+00,2.211859636008739916e+00,3.495372016914200231e+01,2.681032629108913712e-01,4.570136510834931443e+01,9.032155754975970012e+02
2.223940193653109798e+00,2.223940193653109798e+00,3.538244869559999728e+01,2.701603612762801254e-01,4.635718327218048529e+01,9.026338630355890018e+02
2.236256934702399946e+00,2.236256934702399946e+00,3.540914389304825249e+01,2.723178000162429502e-01,4.649235492517812673e+01,9.033722053281959461e+02
2.248062985017900139e+00,2.248062985017900139e+00,3.496658406220375070e+01,2.742889670190796214e-01,4.600186004226632264e+01,9.022912653163079995e+02
2.259028702974319902e+00,2.259028702974319902e+00,3.426203620620074730e+01,2.762559727350611394e-01,4.516371043056920342e+01,9.025453808717429638e+02
2.271443326026199916e+00,2.271443326026199916e+00,3.497464465908699793e+01,2.784056576422755391e-01,4.620227402920188098e+01,9.027199284173550495e+02
2.284150989726189795e+00,2.284150989726189795e+00,3.511937684379525138e+01,2.806701400040947925e-01,4.649864465600768426e+01,9.030912830494339687e+02
2.295964024960989835e+00,2.295964024960989835e+00,3.449424752034249764e+01,2.827609447357223305e-01,4.576655189426266190e+01,9.030888187699019909e+02
2.307177148759369967e+00,2.307177148759369967e+00,3.382102935574950209e+01,2.848257719222920814e-01,4.496608555208765523e+01,9.035925194621089531e+02
2.319064643234010070e+00,2.319064643234010070e+00,3.426590934395800048e+01,2.868806079722118763e-01,4.565127658278970557e+01,9.032300775870679672e+02
2.331884251907470063e+00,2.331884251907470063e+00,3.488059970550249744e+01,2.891048669412182304e-01,4.657368393662780193e+01,9.032546700909730362e+02
2.344334404915569881e+00,2.344334404915569881e+00,3.438913496211174703e+01,2.913367321318635073e-01,4.602006064934131757e+01,9.033444919623429996e+02
2.355972258374099848e+00,2.355972258374099848e+00,3.360141883604224944e+01,2.933940436076616365e-01,4.505853115555274968e+01,9.025900480337439831e+02
2.367802290245890173e+00,2.367802290245890173e+00,3.382052876986575285e+01,2.954814501914828084e-01,4.544711891327132491e+01,9.034332241863010040e+02
2.380727045238019812e+00,2.380727045238019812e+00,3.429785137996074695e+01,2.977286850730210821e-01,4.619222044623801082e+01,9.033201676793399884e+02
2.392895985394719816e+00,2.392895985394719816e+00,3.358134767040599655e+01,2.999144930053589952e-01,4.532620205014886494e+01,9.025743501260880066e+02
2.404476841911669993e+00,2.404476841911669993e+00,3.310609143227350160e+01,3.021387542507086854e-01,4.478422921027009806e+01,9.034142391756180359e+02
2.415468450635669839e+00,2.415468450635669839e+00,3.265734529122700280e+01,3.041258423622401619e-01,4.426505959641733767e+01,9.031460895203050541e+02
2.427686145529150075e+00,2.427686145529150075e+00,3.324535093270250030e+01,3.062517347168832171e-01,4.515796473833553648e+01,9.027360538020730019e+02
2.440236182883380067e+00,2.440236182883380067e+00,3.331176238134499812e+01,3.085045618485467434e-01,4.535022423678885417e+01,9.034568904899059589e+02
2.452156133949760175e+00,2.452156133949760175e+00,3.286830266006300150e+01,3.106031561241210937e-01,4.484050697723107959e+01,9.032017230056229664e+02
2.463472541421650064e+00,2.463472541421650064e+00,3.232100745663049679e+01,3.126884223250365746e-01,4.418590411515475580e+01,9.029407468624409603e+02
2.475868863984940216e+00,2.475868863984940216e+00,3.303740173578250250e+01,3.149759280358541691e-01,4.526871761821958273e+01,9.038369916379449478e+02
2.488597389310600150e+00,2.488597389310600150e+00,3.294728230684999915e+01,3.172757151140200849e-01,4.524917750765847302e+01,9.031801898963750546e+02
2.500643394887450022e+00,2.500643394887450022e+00,3.254367387853574911e+01,3.195964480949964881e-01,4.479871459669040235e+01,9.048205157741899711e+02
2.512053586542609906e+00,2.512053586542609906e+00,3.200455801561474800e+01,3.216789020628653684e-01,4.414842412289300455e+01,9.043769286945459953e+02
2.524157101288440064e+00,2.524157101288440064e+00,3.249410889111450018e+01,3.238568207877537408e-01,4.492145987583524658e+01,9.034253885038200451e+02
2.537284605205059940e+00,2.537284605205059940e+00,3.299573087133475013e+01,3.261779526667419327e-01,4.572092809353468112e+01,9.041046439670029713e+02
2.549709379673000154e+00,2.549709379673000154e+00,3.244541003368799892e+01,3.285674469481631443e-01,4.506592567801346405e+01,9.039575052447620465e+02
2.561345137655739901e+00,2.561345137655739901e+00,3.167753922753025009e+01,3.307603468507654410e-01,4.409596293689552482e+01,9.039751463569699581e+02
2.573314774781469971e+00,2.573314774781469971e+00,3.206586232408874793e+01,3.329263907614009588e-01,4.473330828860127184e+01,9.038536632433530258e+02
2.586377784609790176e+00,2.586377784609790176e+00,3.255897783674299717e+01,3.353455746598429932e-01,4.553124174452505457e+01,9.044830435886980240e+02
2.598381601274009967e+00,2.598381601274009967e+00,3.169956034980724979e+01,3.376947295946989835e-01,4.443367115120668132e+01,9.040507161989810356e+02
2.609919197857379913e+00,2.609919197857379913e+00,3.118336549960075033e+01,3.399294627349375153e-01,4.380790402560408126e+01,9.043435812927780262e+02
2.621069271117450139e+00,2.621069271117450139e+00,3.100696601904925132e+01,3.420394047980682140e-01,4.365209577611606306e+01,9.035460851155220325e+02
2.633412135764960027e+00,2.633412135764960027e+00,3.156343125738199973e+01,3.442462442575978110e-01,4.453366660458335957e+01,9.031544141471390503e+02
2.645920543000099823e+00,2.645920543000099823e+00,3.146255621686574955e+01,3.466132687652401789e-01,4.449653922906691861e+01,9.038023911416529472e+02
2.657745452597739977e+00,2.657745452597739977e+00,3.094136016443374970e+01,3.488377539507685476e-01,4.385687800273108650e+01,9.028122383169829845e+02
2.668709959834810075e+00,2.668709959834810075e+00,3.042223048396400031e+01,3.509887105951996489e-01,4.321390496643049062e+01,9.034823812544350403e+02
2.681458275765180144e+00,2.681458275765180144e+00,3.118576598353675067e+01,3.533525318691725925e-01,4.440332278370868124e+01,9.033584282733500004e+02
2.694033877924079778e+00,2.694033877924079778e+00,3.091287333518274849e+01,3.557196371825142589e-01,4.411908022807849505e+01,9.030419751070439816e+02
2.705904608592390126e+00,2.705904608592390126e+00,3.052137326449150123e+01,3.581202617520508613e-01,4.366502606147835053e+01,9.035392049700019470e+02
2.717049885541200194e+00,2.717049885541200194e+00,3.002172452397649849e+01,3.601454223220931228e-01,4.303727896203963610e+01,9.028958324342969490e+02
2.729427767917509851e+00,2.729427767917509851e+00,3.048327285796399977e+01,3.624970263616948962e-01,4.380180947069524677e+01,9.023447991348799633e+02
2.742280811071399871e+00,2.742280811071399871e+00,3.060309914872049930e+01,3.650205991303211994e-01,4.408510112190136709e+01,9.035467682406309677e+02
2.754221064969899935e+00,2.754221064969899935e+00,3.002309822477399948e+01,3.673403742002330774e-01,4.335003022403172679e+01,9.033340886235240532e+02
2.765328064560890198e+00,2.765328064560890198e+00,2.944296225905425146e+01,3.696169342226690580e-01,4.260927034076573960e+01,9.039051407016810344e+02
2.777856867760419846e+00,2.777856867760419846e+00,3.015588154084975159e+01,3.719791804365231158e-01,4.374420559838038969e+01,9.039132795296610539e+02
2.790610073134299984e+00,2.790610073134299984e+00,3.003642661497000077e+01,3.743599451034491654e-01,4.367477964598442952e+01,9.031998789869250004e+02
2.802293468266729981e+00,2.802293468266729981e+00,2.939518657512974897e+01,3.767933520981023854e-01,4.284651412549722949e+01,9.039288572967050186e+02
2.813179511576890057e+00,2.813179511576890057e+00,2.868633135221899977e+01,3.788572640273111247e-01,4.189967263291892863e+01,9.031377159990370274e+02
2.824922138825059825e+00,2.824922138825059825e+00,2.907211659476149990e+01,3.811048796175802722e-01,4.255870435635314664e+01,9.027058565989140106e+02
2.837430359795690027e+00,2.837430359795690027e+00,2.949275076389324823e+01,3.835764956132614034e-01,4.328131388844840899e+01,9.037602609023449531e+02
2.849348122254010018e+00,2.849348122254010018e+00,2.899029641412199965e+01,3.859233723701089303e-01,4.264391283001971544e+01,9.036599951796230243e+02
2.860399102792139825e+00,2.860399102792139825e+00,2.810077508911500033e+01,3.881988768203586404e-01,4.142961801437954250e+01,9.033326231874530095e+02
2.872492559254169908e+00,2.872492559254169908e+00,2.884421963244675169e+01,3.905585379110520505e-01,4.262616009038082865e+01,9.037428810261189938e+02
2.885115705430509880e+00,2.885115705430509880e+00,2.903304877690975161e+01,3.930266531752024117e-01,4.301123872721180419e+01,9.037976469844579697e+02
2.897275146096939924e+00,2.897275146096939924e+00,2.856230014003824991e+01,3.954744630963167862e-01,4.241754757150695099e+01,9.041505027562379837e+02
2.908743498846889874e+00,2.908743498846889874e+00,2.797211869619775015e+01,3.978305085776625005e-01,4.163906386240930857e+01,9.039978557266299504e+02
2.920291712507609994e+00,2.920291712507609994e+00,2.811987185850750137e+01,3.999934327939408951e-01,4.194964384016940784e+01,9.030350195243950111e+02
2.932610036805269882e+00,2.932610036805269882e+00,2.833229955285800017e+01,4.024762884591957524e-01,4.237161876014472739e+01,9.037598823197190541e+02
2.945420006290079940e+00,2.945420006290079940e+00,2.832503174431624871e+01,4.050859403580471807e-01,4.247144076242940969e+01,9.038411225192249958e+02
2.957077464088799790e+00,2.957077464088799790e+00,2.761393086984750056e+01,4.076007735284947198e-01,4.150945200970780036e+01,9.043525792658330147e+02
2.968611009418959945e+00,2.968611009418959945e+00,2.771811676211650166e+01,4.099066980613680355e-01,4.176225462589248849e+01,9.040174288675190155e+02
2.981076901778580091e+00,2.981076901778580091e+00,2.792337443679575060e+01,4.124413935795601671e-01,4.217828541939977782e+01,9.040998034179209526e+02
2.993236621841790068e+00,2.993236621841790068e+00,2.752175088971850059e+01,4.149129822375949295e-01,4.167450769980951719e+01,9.037540513090790455e+02
3.004873357713219839e+00,3.004873357713219839e+00,2.723794081248350096e+01,4.172876493050956537e-01,4.134281035647735081e+01,9.041353818029169815e+02
3.015758516266939804e+00,3.015758516266939804e+00,2.666788641363374879e+01,4.196424199757041174e-01,4.057298720719300178e+01,9.042850462719800362e+02
3.027504310011860156e+00,3.027504310011860156e+00,2.703265054151425062e+01,4.220487491125682333e-01,4.122703225284271866e+01,9.036525366827850121e+02
3.039749385789039859e+00,3.039749385789039859e+00,2.711155801080175110e+01,4.246150351879332541e-01,4.145361813908997561e+01,9.044006913900379914e+02
3.051357576623559886e+00,3.051357576623559886e+00,2.663276507519174885e+01,4.269701963717301152e-01,4.081756175199737413e+01,9.032610892318190281e+02
3.062456147745249879e+00,3.062456147745249879e+00,2.610924071632324939e+01,4.293133547288668916e-01,4.010907656003867316e+01,9.037345130927859600e+02
3.074553003534679974e+00,3.074553003534679974e+00,2.668382716365150031e+01,4.317448211089880972e-01,4.109154895319297651e+01,9.037652411498130505e+02
3.087287442758679834e+00,3.087287442758679834e+00,2.688706154003750015e+01,4.343425499782778698e-01,4.151221566242269745e+01,9.037600792944430168e+02
3.099440969526769951e+00,3.099440969526769951e+00,2.637065248563875031e+01,4.370500759323254769e-01,4.082529314976500245e+01,9.052858427166939919e+02
3.110645245760680133e+00,3.110645245760680133e+00,2.569213625974949977e+01,4.394864565735743800e-01,3.987188422690260126e+01,9.046431616879999638e+02
3.122329525649549797e+00,3.122329525649549797e+00,2.608546521514649896e+01,4.418872728532172722e-01,4.057960269760112482e+01,9.044029908254740349e+02
3.135104384273290190e+00,3.135104384273290190e+00,2.647631336003550118e+01,4.445087797434508214e-01,4.129573713444761296e+01,9.042146173305809498e+02
3.147547133266929809e+00,3.147547133266929809e+00,2.601848449558024967e+01,4.472030727529480165e-01,4.069113682526212727e+01,9.044481944292780327e+02
3.158991131931539798e+00,3.158991131931539798e+00,2.528876299038525133e+01,4.497830283171440624e-01,3.965207084384223180e+01,9.050928354263310212e+02
3.170791920274500075e+00,3.170791920274500075e+00,2.572534605860699841e+01,4.521964983970855334e-01,4.043408964487341706e+01,9.045080160722139908e+02
3.183738142251970160e+00,3.183738142251970160e+00,2.599042607471350053e+01,4.549014649300972546e-01,4.096138146123360713e+01,9.046406708657740410e+02
3.195835044607520103e+00,3.195835044607520103e+00,2.527771983295674829e+01,4.575405003876980015e-01,3.994341665884645209e+01,9.040756118483840282e+02
3.207485564053059957e+00,3.207485564053059957e+00,2.495535882189869881e+01,4.601571714824332915e-01,3.953734835130661907e+01,9.048838173039259800e+02
3.218577010557059914e+00,3.218577010557059914e+00,2.474373322911559825e+01,4.625619853583038399e-01,3.929645217864985085e+01,9.040293688885869869e+02
3.231144417077299824e+00,3.231144417077299824e+00,2.527082338929174909e+01,4.652410011734689488e-01,4.024120641003685250e+01,9.041971620172259918e+02
3.243703953921790006e+00,3.243703953921790006e+00,2.502479823306200046e+01,4.680691787060340947e-01,3.996229726571448992e+01,9.050047933124010342e+02
3.255653614178299904e+00,3.255653614178299904e+00,2.462604665197432396e+01,4.707019946576769254e-01,3.942920102051844822e+01,9.042153102345760090e+02
3.266943246126170042e+00,3.266943246126170042e+00,2.423569792881607654e+01,4.732160238549768527e-01,3.890188438095047019e+01,9.042087723501030041e+02
3.279971191659570184e+00,3.279971191659570184e+00,2.488493104465305095e+01,4.759058141732872560e-01,4.005158529068663142e+01,9.041332025080920403e+02
3.292350331321360013e+00,3.292350331321360013e+00,2.429490792565047386e+01,4.787301413334979494e-01,3.921255277299051301e+01,9.042551005259159638e+02
3.304386558011170205e+00,3.304386558011170205e+00,2.409335691481827624e+01,4.815703019398826501e-01,3.899784771262093841e+01,9.055019910447299480e+02
3.315763548016549933e+00,3.315763548016549933e+00,2.357470337301492336e+01,4.841440106172417712e-01,3.825668272545745907e+01,9.044133662246169933e+02
3.327756887301799971e+00,3.327756887301799971e+00,2.394453738816082478e+01,4.866332962930411399e-01,3.895369021274973420e+01,9.035552660934630467e+02
3.333901194855569905e+00,3.333901194855569905e+00,1.873552682809532399e+01,4.887666108085157446e-01,3.054460769938449261e+01,9.053119802847500068e+02
3.334265062585469952e+00,3.334265062585469952e+00,1.568731269799172523e+01,4.899596848367854252e-01,2.560562264877872707e+01,9.086251119151710327e+02
3.335114009678359803e+00,3.335114009678359803e+00,1.451955526135862584e+01,4.899344378477501483e-01,2.369895175443620872e+01,9.053194122388960068e+02
3.337774984538560030e+00,3.337774984538560030e+00,1.513688592240215058e+01,4.903444373689729852e-01,2.471669629860378237e+01,9.022319228388370220e+02
3.340290253981950119e+00,3.340290253981950119e+00,1.513994997367262485e+01,4.910304877957109571e-01,2.473866567385100268e+01,9.020259305834770203e+02
3.342502517625689951e+00,3.342502517625689951e+00,1.478004269301892570e+01,4.916184615893523513e-01,2.416478155845157261e+01,9.016515067778530010e+02
3.344392124563460023e+00,3.344392124563460023e+00,1.441042986698447415e+01,4.920624296259650809e-01,2.357094172050351588e+01,9.007729366421699524e+02
3.346119029447439885e+00,3.346119029447439885e+00,1.391170197166502476e+01,4.926618408015359662e-01,2.276882316649528093e+01,9.016494923271239941e+02
3.347523277625440219e+00,3.347523277625440219e+00,1.338528236374260061e+01,4.930332225040575111e-01,2.191538704244861435e+01,9.015751713886860443e+02
3.348716860637070081e+00,3.348716860637070081e+00,1.289816340431569941e+01,4.933170422137810873e-01,2.112383389931246569e+01,9.008805868215860073e+02
3.349877195432779953e+00,3.349877195432779953e+00,1.250405795872212522e+01,4.936884416980096280e-01,2.048599885291926270e+01,9.008714994415639694e+02
3.350890567526219943e+00,3.350890567526219943e+00,1.209886744618414944e+01,4.940349946118953173e-01,1.982902638702908860e+01,9.009808343835179585e+02
3.351635998114939952e+00,3.351635998114939952e+00,1.161430496722459971e+01,4.943499413719448787e-01,1.904086514395067198e+01,9.009249075315890423e+02
3.352258307859299791e+00,3.352258307859299791e+00,1.115910126827657578e+01,4.945096886315913931e-01,1.829751230200327328e+01,9.002630459144710358e+02
3.352850209921600211e+00,3.352850209921600211e+00,1.073088147677479931e+01,4.948136233295202802e-01,1.760071149846128691e+01,9.008902609348300530e+02
3.353306697681550208e+00,3.353306697681550208e+00,1.027187565341592546e+01,4.950732186274803270e-01,1.685222777305826014e+01,9.010833646170799511e+02
3.353595687076449838e+00,3.353595687076449838e+00,9.776162914931774139e+00,4.952020069120519619e-01,1.604101811594691540e+01,9.009574614465240074e+02
3.353882860392329857e+00,3.353882860392329857e+00,9.380248375237000502e+00,4.952896820572507131e-01,1.539273929609617042e+01,9.002741812728349942e+02
3.354062745347619945e+00,3.354062745347619945e+00,8.971407078206549812e+00,4.954906264530591908e-01,1.472480011817043000e+01,9.009954202920199577e+02
3.354230104014280123e+00,3.354230104014280123e+00,8.613634854555124676e+00,4.956101540756255308e-01,1.413927731705306456e+01,9.005035646259780151e+02
3.354329383000730136e+00,3.354329383000730136e+00,8.255619322881100786e+00,4.957034454513604138e-01,1.355285930631185920e+01,9.010025099851189907e+02
3.354404121637339919e+00,3.354404121637339919e+00,7.953859167173500389e+00,4.957751483934547676e-01,1.305841024108301873e+01,9.007173101417720318e+02
3.354458231478929964e+00,3.354458231478929964e+00,7.627967279404400003e+00,4.958893396251525809e-01,1.252480073942155947e+01,9.006328848190610188e+02
3.354480350390080190e+00,3.354480350390080190e+00,7.360405288636674648e+00,4.959702358055773641e-01,1.208645293715939673e+01,9.008243428543210030e+02
3.354521002620459935e+00,3.354521002620459935e+00,7.131071761250500352e+00,4.960355184452825417e-01,1.171063096481175592e+01,9.009993094950909835e+02
3.354540187865500123e+00,3.354540187865500123e+00,6.899503059685224926e+00,4.961014690928612914e-01,1.133109660136318197e+01,9.002709263004360309e+02
3.354581678286200130e+00,3.354581678286200130e+00,6.702817045152174913e+00,4.962324778589660701e-01,1.100952019086112621e+01,9.004398412071169560e+02
3.354611666873100084e+00,3.354611666873100084e+00,6.512686377391225356e+00,4.962259564569924120e-01,1.069715674656131377e+01,8.997301314957439899e+02
3.354640351608400017e+00,3.354640351608400017e+00,6.315865321084849882e+00,4.963711480928726383e-01,1.037538237446911360e+01,9.005981627851720077e+02
3.354660002514719963e+00,3.354660002514719963e+00,6.137219024822124780e+00,4.963448243614868582e-01,1.008164593347537519e+01,8.996356339193880558e+02
3.354681143537160182e+00,3.354681143537160182e+00,5.934073124080899930e+00,4.964466280866182690e-01,9.748929389524757738e+00,8.996868445537979824e+02
3.354699956253170079e+00,3.354699956253170079e+00,5.766852991655475158e+00,4.964873358439333972e-01,9.474593605886086678e+00,9.002416636794810074e+02
3.354553459212179956e+00,3.354553459212179956e+00,5.552838556468475240e+00,4.965828763859481687e-01,9.123852380269150686e+00,9.013164234347640331e+02
3.354019485414029944e+00,3.354019485414029944e+00,4.736980190500625021e+00,4.964854746204255265e-01,7.782559873755033664e+00,8.990037250332529766e+02
3.352801688015460080e+00,3.352801688015460080e+00,3.261849051341425110e+00,4.964922610376428791e-01,5.359048760546508028e+00,8.994244574569170254e+02
3.351561585441229951e+00,3.351561585441229951e+00,2.044374123215674910e+00,4.964797975132959618e-01,3.358758756271607027e+00,9.003438474610450157e+02
3.350478783249859926e+00,3.350478783249859926e+00,1.250832574442030110e+00,4.963593751846947510e-01,2.054779954953226628e+00,9.003214132972060497e+02
3.349594073370099956e+00,3.349594073370099956e+00,6.975186988711350455e-01,4.961982574775575805e-01,1.145650158931207141e+00,8.996160971000789459e+02
3.348959702998400179e+00,3.348959702998400179e+00,3.570725675672299926e-01,4.962489914987913697e-01,5.865090057911253041e-01,9.002035874873399734e+02